{
	"id": "oval:org.opensuse.security:def:20169015",
	"version": "1",
	"class": "vulnerability",
	"metadata": {
		"title": "CVE-2016-9015",
		"affected": {
			"family": "unix",
			"platform": [
				"SUSE Linux Enterprise Desktop 12 SP4"
			]
		},
		"reference": [
			{
				"ref_id": "Mitre CVE-2016-9015",
				"ref_url": "https://cve.mitre.org/cgi-bin/cvename.cgi?name=CVE-2016-9015",
				"source": "CVE"
			},
			{
				"ref_id": "SUSE CVE-2016-9015",
				"ref_url": "https://www.suse.com/security/cve/CVE-2016-9015",
				"source": "SUSE CVE"
			},
			{
				"ref_id": "SUSE-SU-2019:0139-1",
				"ref_url": "https://lists.suse.com/pipermail/sle-security-updates/2019-January/005056.html",
				"source": "SUSE-SU"
			},
			{
				"ref_id": "openSUSE-SU-2019:0159-1",
				"ref_url": "https://lists.opensuse.org/opensuse-security-announce/2019-02/msg00014.html",
				"source": "SUSE-SU"
			},
			{
				"ref_id": "unknown",
				"ref_url": "https://lists.suse.com/archive/suse-security-announce/2007-Jun/0001.html",
				"source": "SUSE-SU"
			}
		],
		"description": "\n    Versions 1.17 and 1.18 of the Python urllib3 library suffer from a vulnerability that can cause them, in certain configurations, to not correctly validate TLS certificates. This places users of the library with those configurations at risk of man-in-the-middle and information leakage attacks. This vulnerability affects users using versions 1.17 and 1.18 of the urllib3 library, who are using the optional PyOpenSSL support for TLS instead of the regular standard library TLS backend, and who are using OpenSSL 1.1.0 via PyOpenSSL. This is an extremely uncommon configuration, so the security impact of this vulnerability is low.\n    ",
		"advisory": {
			"from": "security@suse.de",
			"severity": "Low",
			"cve": [
				{
					"text": "CVE-2016-9015",
					"href": "https://www.suse.com/security/cve/CVE-2016-9015/",
					"impact": "low",
					"cvss3": "3.7/CVSS:3.1/AV:N/AC:H/PR:N/UI:N/S:U/C:L/I:N/A:N"
				}
			],
			"bugzilla": [
				{
					"text": "SUSE bug 1023502",
					"href": "https://bugzilla.suse.com/1023502"
				},
				{
					"text": "SUSE bug 1024540",
					"href": "https://bugzilla.suse.com/1024540"
				}
			],
			"issued": {
				"date": "2022-03-01"
			},
			"updated": {
				"date": "2022-03-01"
			},
			"affected_cpe_list": {
				"cpe": [
					"cpe:/o:suse:sled:12:sp4"
				]
			}
		}
	},
	"criteria": {
		"operator": "AND",
		"criterias": [
			{
				"operator": "OR",
				"criterions": [
					{
						"test_ref": "oval:org.opensuse.security:tst:2009561941",
						"comment": "python-setuptools-40.6.2-4.12.23 is installed"
					},
					{
						"test_ref": "oval:org.opensuse.security:tst:2009561942",
						"comment": "python3-setuptools-40.6.2-4.12.23 is installed"
					}
				]
			}
		],
		"criterions": [
			{
				"test_ref": "oval:org.opensuse.security:tst:2009239879",
				"comment": "SUSE Linux Enterprise Desktop 12 SP4 is installed"
			}
		]
	}
}
