{
	"id": "oval:org.opensuse.security:def:20103493",
	"version": "1",
	"class": "vulnerability",
	"metadata": {
		"title": "CVE-2010-3493",
		"affected": {
			"family": "unix",
			"platform": [
				"SUSE Linux Enterprise Desktop 12 SP4"
			]
		},
		"reference": [
			{
				"ref_id": "Mitre CVE-2010-3493",
				"ref_url": "https://cve.mitre.org/cgi-bin/cvename.cgi?name=CVE-2010-3493",
				"source": "CVE"
			},
			{
				"ref_id": "SUSE CVE-2010-3493",
				"ref_url": "https://www.suse.com/security/cve/CVE-2010-3493",
				"source": "SUSE CVE"
			},
			{
				"ref_id": "SUSE-SR:2010:024",
				"ref_url": "https://lists.opensuse.org/opensuse-security-announce/2010-12/msg00006.html",
				"source": "SUSE-SU"
			},
			{
				"ref_id": "SUSE-SR:2011:002",
				"ref_url": "https://lists.opensuse.org/opensuse-security-announce/2011-01/msg00006.html",
				"source": "SUSE-SU"
			},
			{
				"ref_id": "openSUSE-SU-2010:1049-1",
				"ref_url": "https://lists.opensuse.org/opensuse-updates/2010-12/msg00027.html",
				"source": "SUSE-SU"
			},
			{
				"ref_id": "openSUSE-SU-2010:1051-1",
				"ref_url": "https://lists.opensuse.org/opensuse-updates/2010-12/msg00028.html",
				"source": "SUSE-SU"
			}
		],
		"description": "\n    Multiple race conditions in smtpd.py in the smtpd module in Python 2.6, 2.7, 3.1, and 3.2 alpha allow remote attackers to cause a denial of service (daemon outage) by establishing and then immediately closing a TCP connection, leading to the accept function having an unexpected return value of None, an unexpected value of None for the address, or an ECONNABORTED, EAGAIN, or EWOULDBLOCK error, or the getpeername function having an ENOTCONN error, a related issue to CVE-2010-3492.\n    ",
		"advisory": {
			"from": "security@suse.de",
			"severity": "Moderate",
			"cve": [
				{
					"text": "CVE-2010-3493",
					"href": "https://www.suse.com/security/cve/CVE-2010-3493/",
					"impact": "moderate"
				}
			],
			"bugzilla": [
				{
					"text": "SUSE bug 638233",
					"href": "https://bugzilla.suse.com/638233"
				},
				{
					"text": "SUSE bug 666027",
					"href": "https://bugzilla.suse.com/666027"
				}
			],
			"issued": {
				"date": "2022-05-20"
			},
			"updated": {
				"date": "2022-05-20"
			},
			"affected_cpe_list": {
				"cpe": [
					"cpe:/o:suse:sled:12:sp4"
				]
			}
		}
	},
	"criteria": {
		"operator": "AND",
		"criterions": [
			{
				"test_ref": "oval:org.opensuse.security:tst:2009239879",
				"comment": "SUSE Linux Enterprise Desktop 12 SP4 is installed"
			},
			{
				"test_ref": "oval:org.opensuse.security:tst:2009334164",
				"comment": "python is affected"
			}
		]
	}
}
