{
	"id": "oval:org.opensuse.security:def:202015523",
	"version": "1",
	"class": "vulnerability",
	"metadata": {
		"title": "CVE-2020-15523",
		"affected": {
			"family": "unix",
			"platform": [
				"SUSE Linux Micro 6.1"
			]
		},
		"reference": [
			{
				"ref_id": "Mitre CVE-2020-15523",
				"ref_url": "https://cve.mitre.org/cgi-bin/cvename.cgi?name=CVE-2020-15523",
				"source": "CVE"
			},
			{
				"ref_id": "SUSE CVE-2020-15523",
				"ref_url": "https://www.suse.com/security/cve/CVE-2020-15523",
				"source": "SUSE CVE"
			},
			{
				"ref_id": "SUSE-FU-2022:0444-1",
				"ref_url": "https://lists.suse.com/pipermail/sle-updates/2022-February/021718.html",
				"source": "SUSE-SU"
			},
			{
				"ref_id": "SUSE-FU-2022:0445-1",
				"ref_url": "https://lists.suse.com/pipermail/sle-updates/2022-February/021715.html",
				"source": "SUSE-SU"
			},
			{
				"ref_id": "SUSE-FU-2022:0447-1",
				"ref_url": "https://lists.suse.com/pipermail/sle-updates/2022-February/021720.html",
				"source": "SUSE-SU"
			},
			{
				"ref_id": "SUSE-FU-2022:0450-1",
				"ref_url": "https://lists.suse.com/pipermail/sle-updates/2022-February/021717.html",
				"source": "SUSE-SU"
			},
			{
				"ref_id": "SUSE-FU-2022:0452-1",
				"ref_url": "https://lists.suse.com/pipermail/sle-updates/2022-February/021719.html",
				"source": "SUSE-SU"
			},
			{
				"ref_id": "SUSE-FU-2022:0454-1",
				"ref_url": "https://lists.suse.com/pipermail/sle-updates/2022-February/021714.html",
				"source": "SUSE-SU"
			},
			{
				"ref_id": "SUSE-FU-2022:0456-1",
				"ref_url": "https://lists.suse.com/pipermail/sle-updates/2022-February/021716.html",
				"source": "SUSE-SU"
			},
			{
				"ref_id": "unknown",
				"ref_url": "https://lists.suse.com/pipermail/neuvector-updates/2023-November/000021.html",
				"source": "SUSE-SU"
			}
		],
		"description": "\n    In Python 3.6 through 3.6.10, 3.7 through 3.7.8, 3.8 through 3.8.4rc1, and 3.9 through 3.9.0b4 on Windows, a Trojan horse python3.dll might be used in cases where CPython is embedded in a native application. This occurs because python3X.dll may use an invalid search path for python3.dll loading (after Py_SetPath has been used). NOTE: this issue CANNOT occur when using python.exe from a standard (non-embedded) Python installation on Windows.\n    ",
		"advisory": {
			"from": "security@suse.de",
			"severity": "Important",
			"cve": [
				{
					"text": "CVE-2020-15523 at SUSE",
					"href": "https://www.suse.com/security/cve/CVE-2020-15523/"
				},
				{
					"text": "CVE-2020-15523 at NVD",
					"href": "https://nvd.nist.gov/vuln/detail/CVE-2020-15523",
					"impact": "high",
					"cvss3": "7.8/CVSS:3.1/AV:L/AC:L/PR:N/UI:R/S:U/C:H/I:H/A:H"
				}
			],
			"bugzilla": [
				{
					"text": "SUSE bug 1173745",
					"href": "https://bugzilla.suse.com/1173745"
				}
			],
			"issued": {
				"date": "2024-11-24"
			},
			"updated": {
				"date": "2024-12-23"
			},
			"affected_cpe_list": {
				"cpe": [
					"cpe:/o:suse:sl-micro:6.1"
				]
			}
		}
	},
	"criteria": {
		"operator": "AND",
		"criterias": [
			{
				"operator": "OR",
				"criterions": [
					{
						"test_ref": "oval:org.opensuse.security:tst:2009954414",
						"comment": "libpython3_11-1_0-3.11.8-slfo.1.1_3.12 is installed"
					},
					{
						"test_ref": "oval:org.opensuse.security:tst:2009954415",
						"comment": "python311-3.11.8-slfo.1.1_3.3 is installed"
					},
					{
						"test_ref": "oval:org.opensuse.security:tst:2009954416",
						"comment": "python311-base-3.11.8-slfo.1.1_3.12 is installed"
					},
					{
						"test_ref": "oval:org.opensuse.security:tst:2009954417",
						"comment": "python311-curses-3.11.8-slfo.1.1_3.3 is installed"
					}
				]
			}
		],
		"criterions": [
			{
				"test_ref": "oval:org.opensuse.security:tst:2009954035",
				"comment": "SUSE Linux Micro 6.1 is installed"
			}
		]
	}
}
