{
	"id": "oval:org.opensuse.security:def:202445230",
	"version": "1",
	"class": "vulnerability",
	"metadata": {
		"title": "CVE-2024-45230",
		"affected": {
			"family": "unix",
			"platform": [
				"SUSE Linux Enterprise Module for Package Hub 15 SP6"
			]
		},
		"reference": [
			{
				"ref_id": "Mitre CVE-2024-45230",
				"ref_url": "https://cve.mitre.org/cgi-bin/cvename.cgi?name=CVE-2024-45230",
				"source": "CVE"
			},
			{
				"ref_id": "SUSE CVE-2024-45230",
				"ref_url": "https://www.suse.com/security/cve/CVE-2024-45230",
				"source": "SUSE CVE"
			},
			{
				"ref_id": "SUSE-SU-2024:3139-1",
				"ref_url": "https://lists.suse.com/pipermail/sle-security-updates/2024-September/019372.html",
				"source": "SUSE-SU"
			},
			{
				"ref_id": "SUSE-SU-2024:3161-1",
				"ref_url": "https://lists.suse.com/pipermail/sle-updates/2024-September/036802.html",
				"source": "SUSE-SU"
			},
			{
				"ref_id": "SUSE-SU-2024:3187-1",
				"ref_url": "https://lists.suse.com/pipermail/sle-security-updates/2024-September/019406.html",
				"source": "SUSE-SU"
			},
			{
				"ref_id": "openSUSE-SU-2024:0282-1",
				"ref_url": "https://lists.opensuse.org/archives/list/security-announce@lists.opensuse.org/thread/V6QMWZEDSOESTQCAUDVZR5DAIT6TFV27/",
				"source": "SUSE-SU"
			}
		],
		"description": "\n    An issue was discovered in Django 5.1 before 5.1.1, 5.0 before 5.0.9, and 4.2 before 4.2.16. The urlize() and urlizetrunc() template filters are subject to a potential denial-of-service attack via very large inputs with a specific sequence of characters.\n    ",
		"advisory": {
			"from": "security@suse.de",
			"severity": "Important",
			"cve": [
				{
					"text": "CVE-2024-45230 at SUSE",
					"href": "https://www.suse.com/security/cve/CVE-2024-45230/",
					"impact": "high",
					"cvss3": "7.5/CVSS:3.1/AV:N/AC:L/PR:N/UI:N/S:U/C:N/I:N/A:H"
				},
				{
					"text": "CVE-2024-45230 at NVD",
					"href": "https://nvd.nist.gov/vuln/detail/CVE-2024-45230"
				}
			],
			"bugzilla": [
				{
					"text": "SUSE bug 1229823",
					"href": "https://bugzilla.suse.com/1229823"
				}
			],
			"issued": {
				"date": "2024-09-07"
			},
			"updated": {
				"date": "2024-10-09"
			},
			"affected_cpe_list": {
				"cpe": [
					"cpe:/o:suse:packagehub:15:sp6"
				]
			}
		}
	},
	"criteria": {
		"operator": "AND",
		"criterions": [
			{
				"test_ref": "oval:org.opensuse.security:tst:2009856293",
				"comment": "SUSE Linux Enterprise Module for Package Hub 15 SP6 is installed"
			},
			{
				"test_ref": "oval:org.opensuse.security:tst:2009941506",
				"comment": "python311-Django-4.2.11-150600.3.9.1 is installed"
			}
		]
	}
}
