{
	"id": "oval:org.opensuse.security:def:20177233",
	"version": "1",
	"class": "vulnerability",
	"metadata": {
		"title": "CVE-2017-7233",
		"affected": {
			"family": "unix",
			"platform": [
				"openSUSE Tumbleweed"
			]
		},
		"reference": [
			{
				"ref_id": "Mitre CVE-2017-7233",
				"ref_url": "https://cve.mitre.org/cgi-bin/cvename.cgi?name=CVE-2017-7233",
				"source": "CVE"
			},
			{
				"ref_id": "SUSE CVE-2017-7233",
				"ref_url": "https://www.suse.com/security/cve/CVE-2017-7233",
				"source": "SUSE CVE"
			},
			{
				"ref_id": "SUSE-SU-2018:0973-1",
				"ref_url": "https://lists.suse.com/pipermail/sle-security-updates/2018-April/003895.html",
				"source": "SUSE-SU"
			},
			{
				"ref_id": "SUSE-SU-2018:1102-1",
				"ref_url": "https://lists.suse.com/pipermail/sle-security-updates/2018-April/003965.html",
				"source": "SUSE-SU"
			},
			{
				"ref_id": "openSUSE-SU-2023:0077-1",
				"ref_url": "https://lists.opensuse.org/archives/list/security-announce@lists.opensuse.org/thread/OGS4NP24275NERRPQV6A6EONV6W3C2SK/",
				"source": "SUSE-SU"
			}
		],
		"description": "\n    Django 1.10 before 1.10.7, 1.9 before 1.9.13, and 1.8 before 1.8.18 relies on user input in some cases to redirect the user to an \"on success\" URL. The security check for these redirects (namely ``django.utils.http.is_safe_url()``) considered some numeric URLs \"safe\" when they shouldn't be, aka an open redirect vulnerability. Also, if a developer relies on ``is_safe_url()`` to provide safe redirect targets and puts such a URL into a link, they could suffer from an XSS attack.\n    ",
		"advisory": {
			"from": "security@suse.de",
			"severity": "Low",
			"cve": [
				{
					"text": "CVE-2017-7233 at SUSE",
					"href": "https://www.suse.com/security/cve/CVE-2017-7233/"
				},
				{
					"text": "CVE-2017-7233 at NVD",
					"href": "https://nvd.nist.gov/vuln/detail/CVE-2017-7233",
					"impact": "medium",
					"cvss3": "6.1/CVSS:3.0/AV:N/AC:L/PR:N/UI:R/S:C/C:L/I:L/A:N"
				}
			],
			"bugzilla": [
				{
					"text": "SUSE bug 1031450",
					"href": "https://bugzilla.suse.com/1031450"
				}
			],
			"issued": {
				"date": "2022-06-30"
			},
			"updated": {
				"date": "2024-09-01"
			},
			"affected_cpe_list": {
				"cpe": [
					"cpe:/o:opensuse:tumbleweed"
				]
			}
		}
	},
	"criteria": {
		"operator": "AND",
		"criterias": [
			{
				"operator": "OR",
				"criterions": [
					{
						"test_ref": "oval:org.opensuse.security:tst:2009937554",
						"comment": "python310-Django-4.2.11-2.1 is installed"
					},
					{
						"test_ref": "oval:org.opensuse.security:tst:2009939568",
						"comment": "python310-Django4-4.2.14-1.1 is installed"
					},
					{
						"test_ref": "oval:org.opensuse.security:tst:2009937555",
						"comment": "python311-Django-4.2.11-2.1 is installed"
					},
					{
						"test_ref": "oval:org.opensuse.security:tst:2009939569",
						"comment": "python311-Django4-4.2.14-1.1 is installed"
					},
					{
						"test_ref": "oval:org.opensuse.security:tst:2009937556",
						"comment": "python312-Django-4.2.11-2.1 is installed"
					},
					{
						"test_ref": "oval:org.opensuse.security:tst:2009939570",
						"comment": "python312-Django4-4.2.14-1.1 is installed"
					},
					{
						"test_ref": "oval:org.opensuse.security:tst:2009912572",
						"comment": "python36-Django-3.2.7-2.3 is installed"
					},
					{
						"test_ref": "oval:org.opensuse.security:tst:2009912573",
						"comment": "python38-Django-3.2.7-2.3 is installed"
					},
					{
						"test_ref": "oval:org.opensuse.security:tst:2009912574",
						"comment": "python39-Django-3.2.7-2.3 is installed"
					}
				]
			}
		],
		"criterions": [
			{
				"test_ref": "oval:org.opensuse.security:tst:2009634834",
				"comment": "openSUSE Tumbleweed is installed"
			}
		]
	}
}
